Workbook

Sheet Reserves
A1: Year | B1: 2025 | C1: 2026 | D1: 2027 | E1: 2028 | F1: 2029 | G1: 2030 | H1: 2031 | I1: 2032 | J1: 2033 | K1: 2034 | L1: 2035 | M1: 2036 | N1: 2037 | O1: 2038 | P1: 2039 | Q1: 2040 | R1: 2041 | S1: 2042 | T1: 2043 | U1: 2044 | V1: 2045 | W1: 2046 | X1: 2047 | Y1: 2048 | Z1: 2049 | AA1: 2050 | AB1: 2051 | AC1: 2052 | AD1: 2053 | AE1: 2054 | AF1: 2055 | AG1: 2056
A2: RESERVES (Cash Surplus Yr-End) | B2: ='30 Year'!M47 -> 528488.74 | C2: ='30 Year'!AC47 -> 268775.72 | D2: ='30 Year'!AS47 -> 228405.76 | E2: ='30 Year'!BG47 -> 350309.58 | F2: ='30 Year'!BU47 -> 527869.51 | G2: ='30 Year'!BX47 -> 686202.63 | H2: ='30 Year'!BY47 -> 951900.25 | I2: ='30 Year'!BZ47 -> 1077903.8 | J2: ='30 Year'!CA47 -> 1309219.9 | K2: ='30 Year'!CB47 -> 1522556 | L2: ='30 Year'!CC47 -> 1163888.6 | M2: ='30 Year'!CD47 -> 927245.83 | N2: ='30 Year'!CE47 -> 762843.22 | ... AG2: ='30 Year'!CX47 -> 1884857.2
A3: Minimum Year-End Reserve Start 2030 | C3: 450000 | D3: =C3*(1+Inflation!$J$13) -> 465444.83 | E3: =D3*(1+Inflation!$J$13) -> 481419.75 | F3: =E3*(1+Inflation!$J$13) -> 497942.97 | G3: =F3*(1+Inflation!$J$13) -> 515033.29 | H3: =G3*(1+Inflation!$J$13) -> 532710.18 | I3: =H3*(1+Inflation!$J$13) -> 550993.77 | J3: =I3*(1+Inflation!$J$13) -> 569904.89 | K3: =J3*(1+Inflation!$J$13) -> 589465.08 | ... AG3: =AF3*(1+Inflation!$J$13) -> 1238464
A4: Monthly Cash-In / Unit | B4: =sum('30 Year'!B48:B49) -> 800 | C4: =SUM('30 Year'!R48:R49) -> 425 | D4: =SUM('30 Year'!AH48:AH49) -> 425 | E4: =SUM('30 Year'!AV48:AV49) -> 475 | F4: =SUM('30 Year'!BJ48:BJ49) -> 425 | G4: =SUM('30 Year'!BX48:BX49) -> 425 | H4: =SUM('30 Year'!BY48:BY49) -> 500 | I4: =SUM('30 Year'!BZ48:BZ49) -> 500 | J4: =SUM('30 Year'!CA48:CA49) -> 500 | K4: =SUM('30 Year'!CB48:CB49) -> 500 | L4: =SUM('30 Year'!CC48:CC49) -> 500 | M4: =SUM('30 Year'!CD48:CD49) -> 575 | N4: =SUM('30 Year'!CE48:CE49) -> 575 | ... AG4: =SUM('30 Year'!CX48:CX49) -> 850
B5: THIS CASH PROJECTION REPRESENTS THE BEST ESTIMATE OF THE FINANCIAL OUTLOOK. THE RIDGE PARK BOARD MAY CHANGE IT AT ANYTIME.
A6: Inflation Rate Sources: Federal Reserve Bank of St. Louis Producer Price Index by Industry for Building Maintenance, New Construction, and General Inflation.
A7: Ridge Park Property Data Sources: square footages, linear feet, and other dimensions measured and estimated from Ridge Park blue prints.
A8: Financial Data Sources: Bank Statements, Financial Statements from Accoutant, Ridge Park Annual Budget, Max Property Insurance Deductible, and cost estimates from Budget and Maintenance Committees.
A9: Assumptions: All Projects in each Annual Budget are completed. Current Inflation Rates are used for all future years.
C11: CLICK CHART AND HOVER CURSOR OVER BAR TO DISPLAY RESERVE BALANCE
A46: FOR DETAILS ON HOW THIS CHART WAS BUILT CLICK THIS LINK AND REQUEST ACCESS | G46: Ridge Park Budget Projection
A49: STANDARD FORMULA FOR FUTURE VALUES:
A51: FV = PV x (1 + r)^n
A52: PV = Present Value
A53: r = Interest or Inflation Rate (Annual %)
A54: n = Number of Compounding Periods (Years)

Sheet 30 Year
A1: FUNDING PLAN | B1: 1 | C1: 2 | D1: 3 | E1: 4 | F1: 5 | G1: 6 | H1: 7 | I1: 8 | J1: 9 | K1: 10 | L1: 11 | M1: 12 | Q1: FUNDING PLAN | R1: 1 | S1: 2 | T1: 3 | U1: 4 | V1: 5 | W1: 6 | X1: 7 | Y1: 8 | Z1: 9 | AA1: 10 | AB1: 11 | AC1: 12 | AG1: FUNDING PLAN | AU1: FUNDING PLAN | BI1: FUNDING PLAN | BW1: FUNDING PLAN
A2: 2025 Budget Projection GREEN = Bank Record or Check Register BLUE = Budgeted Averages & Estimates, Bids, BLACK = Formula Results | B2: Jan | C2: Feb | D2: Mar | E2: Apr | F2: May | G2: Jun | H2: July | I2: Aug | J2: Sep | K2: Oct | L2: Nov | M2: Dec | N2: Projected Total | O2: Budgeted Total | P2: Projected Over (+) Under (-) Budget | Q2: 2026 Budget Projection GREEN = Bank Record Numbers BLUE = Budget Number/Averages & Bids BLACK = Other Formula Results | R2: Jan | S2: Feb | T2: Mar | U2: Apr | V2: May | W2: Jun | X2: July | Y2: Aug | Z2: Sep | AA2: Oct | AB2: Nov | AC2: Dec | AD2: Projected Total | AE2: Budgeted Total | AF2: Projected Over (+) Under (-) Budget | AG2: PROJECTED Operating & Reserves Account Balances | AH2: Jan | AI2: Feb | AJ2: Mar | AK2: Apr | AL2: May | AM2: Jun | AN2: July | AO2: Aug | AP2: Sep | AQ2: Oct | AR2: Nov | AS2: Dec | AT2: Total 2027 | AU2: PROJECTED Operating & Reserves Account Balances | AV2: Jan | AW2: Feb | AX2: Mar | AY2: Apr | AZ2: May | BA2: Jun | BB2: July | BC2: Aug | BD2: Sep | BE2: Oct | BF2: Nov | BG2: Dec | BH2: Total 2028 | BI2: PROJECTED Operating & Reserves Account Balances | BJ2: Jan | BK2: Feb | BL2: Mar | BM2: Apr | BN2: May | BO2: Jun | BP2: July | BQ2: Aug | BR2: Sep | BS2: Oct | BT2: Nov | BU2: Dec | BV2: Total 2029 | BW2: PROJECTED Operating & Reserves Account Balances
B3: 2025 | C3: 2025 | D3: 2025 | E3: 2025 | F3: 2025 | G3: 2025 | H3: 2025 | I3: 2025 | J3: 2025 | K3: 2025 | L3: 2025 | M3: 2025 | N3: 2025 | O3: 2025 | P3: 2025 | R3: 2026 | S3: 2026 | T3: 2026 | U3: 2026 | V3: 2026 | W3: 2026 | X3: 2026 | Y3: 2026 | Z3: 2026 | AA3: 2026 | AB3: 2026 | AC3: 2026 | AD3: 2026 | AE3: 2026 | AH3: 2027 | AI3: 2027 | AJ3: 2027 | AK3: 2027 | AL3: 2027 | AM3: 2027 | AN3: 2027 | AO3: 2027 | AP3: 2027 | AQ3: 2027 | AR3: 2027 | AS3: 2027 | AT3: 2027 | AV3: 2028 | AW3: 2028 | AX3: 2028 | AY3: 2028 | AZ3: 2028 | BA3: 2028 | BB3: 2028 | BC3: 2028 | BD3: 2028 | BE3: 2028 | BF3: 2028 | BG3: 2028 | BH3: 2028 | BJ3: 2029 | BK3: 2029 | BL3: 2029 | BM3: 2029 | BN3: 2029 | BO3: 2029 | BP3: 2029 | BQ3: 2029 | BR3: 2029 | BS3: 2029 | BT3: 2029 | BU3: 2029 | BV3: 2029 | BX3: 2030 | BY3: 2031 | BZ3: 2032 | CA3: 2033 | CB3: 2034 | CC3: 2035 | CD3: 2036 | CE3: 2037 | CF3: 2038 | CG3: 2039 | CH3: 2040 | CI3: 2041 | CJ3: 2042 | CK3: 2043 | CL3: 2044 | CM3: 2045 | CN3: 2046 | CO3: 2047 | CP3: 2048 | CQ3: 2049 | CR3: 2050 | CS3: 2051 | CT3: 2052 | CU3: 2053 | CV3: 2054 | CW3: 2055 | CX3: 2056
A4: Operating Account (checking) | B4: 122944 | C4: 297940 | D4: 116875 | E4: 92821 | F4: 99109 | G4: 158512 | H4: 202997 | I4: 65081 | J4: 36737 | K4: =sum(J4+J16-J46-J5+J6+J48) -> 75293 | L4: 39900 | M4: 86497 | Q4: Operating Account (checking) | R4: 77854.91 | S4: 124896.59 | T4: 152070 | U4: =sum(T4+T16-T46-T5+T6) -> 161117.56 | V4: 113551 | W4: =sum(V4+V16-V46-V5+V6) -> 117195.81 | X4: =sum(W4+W16-W46-W5+W6) -> 89614.617 | Y4: =sum(X4+X16-X46-X5+X6) -> 68275.782 | Z4: =sum(Y4+Y16-Y46-Y5+Y6) -> 89345.03 | AA4: =sum(Z4+Z16-Z46-Z5+Z6) -> 85909.493 | AB4: =sum(AA4+AA16-AA46-AA5+AA6) -> 79319.85 | AC4: =sum(AB4+AB16-AB46-AB5+AB6) -> 47177.158 | AG4: Operating Account (checking) | AH4: =sum(AC4+AC16-AC46-AC5+AC6) -> 58224.717 | AI4: =sum(AH4+AH16-AH46-AH5+AH6) -> 69625.346 | AJ4: =sum(AI4+AI16-AI46-AI5+AI6) -> 81946.025 | AK4: =sum(AJ4+AJ16-AJ46-AJ5+AJ6) -> 92283.927 | AL4: =sum(AK4+AK16-AK46-AK5+AK6) -> 81780.094 | AM4: =sum(AL4+AL16-AL46-AL5+AL6) -> 63988.109 | AN4: =sum(AM4+AM16-AM46-AM5+AM6) -> 22255.729 | AO4: =sum(AN4+AN16-AN46-AN5+AN6) -> 39333.95 | AP4: =sum(AO4+AO16-AO46-AO5+AO6) -> 48412.17 | ... AS4: =sum(AR4+AR16-AR46-AR5+AR6) -> 80466.862 | AU4: Operating Account (checking) | AV4: =sum(AS4+AS16-AS46-AS5+AS6) -> 82854.764 | AW4: =sum(AV4+AV16-AV46-AV5+AV6) -> 99428.736 | AX4: =sum(AW4+AW16-AW46-AW5+AW6) -> 116920.76 | AY4: =sum(AX4+AX16-AX46-AX5+AX6) -> 132380.44 | AZ4: =sum(AY4+AY16-AY46-AY5+AY6) -> 139302.84 | BA4: =sum(AZ4+AZ16-AZ46-AZ5+AZ6) -> 87831.745 | BB4: =sum(BA4+BA16-BA46-BA5+BA6) -> 108437.31 | BC4: =sum(BB4+BB16-BB46-BB5+BB6) -> 129042.88 | BD4: =sum(BC4+BC16-BC46-BC5+BC6) -> 149020.35 | ... BG4: =sum(BF4+BF16-BF46-BF5+BF6) -> 192197.65 | BI4: Operating Account (checking) | BJ4: =sum(BG4+BG16-BG46-BG5+BG6) -> 209758.58 | BK4: =sum(BJ4+BJ16-BJ46-BJ5+BJ6) -> 217640.65 | BL4: =sum(BK4+BK16-BK46-BK5+BK6) -> 226438.72 | BM4: =sum(BL4+BL16-BL46-BL5+BL6) -> 233153.63 | BN4: =sum(BM4+BM16-BM46-BM5+BM6) -> 231301.36 | BO4: =sum(BN4+BN16-BN46-BN5+BN6) -> 243580.64 | BP4: =sum(BO4+BO16-BO46-BO5+BO6) -> 255859.91 | BQ4: =sum(BP4+BP16-BP46-BP5+BP6) -> 268139.18 | BR4: =sum(BQ4+BQ16-BQ46-BQ5+BQ6) -> 279767.83 | ... BU4: =sum(BT4+BT16-BT46-BT5+BT6) -> 318449.82 | BW4: Operating Account (checking) | BX4: =sum(BU4+BU16-BU46-BU5+BU6) -> 327318.51 | BY4: =sum(BX4+BX16-BX46-BX5+BX6) -> 555651.63 | BZ4: =sum(BY4+BY16-BY46-BY5+BY6) -> 761349.25 | CA4: =sum(BZ4+BZ16-BZ46-BZ5+BZ6) -> 827352.78 | CB4: =sum(CA4+CA16-CA46-CA5+CA6) -> 998668.91 | CC4: =sum(CB4+CB16-CB46-CB5+CB6) -> 1152005 | CD4: =sum(CC4+CC16-CC46-CC5+CC6) -> 733337.59 | CE4: =sum(CD4+CD16-CD46-CD5+CD6) -> 536694.83 | CF4: =sum(CE4+CE16-CE46-CE5+CE6) -> 312292.22 | ... CX4: =sum(CW4+CW16-CW46-CW5+CW6) -> 130610.03
A5: Auto Transfer to Reserves | B5: 5000 | C5: 256000 | D5: 55000 | E5: 56000 | F5: 5000 | G5: 5000 | H5: 5000 | I5: 5000 | J5: 5000 | K5: 5000 | L5: 5000 | M5: 5000 | N5: =SUM(B5:M5) -> 412000 | O5: 170000 | P5: =N5-O5 -> 242000 | Q5: Auto Transfer to Reserves | R5: 5000 | S5: 5000 | T5: 5000 | U5: 5000 | V5: 5000 | W5: 5000 | X5: 5000 | Y5: 5000 | Z5: 5000 | AA5: 5000 | AB5: 5000 | AC5: 5000 | AG5: Auto Transfer to Reserves | AH5: 5000 | AI5: 5000 | AJ5: 5000 | AK5: 5000 | AL5: 5000 | AM5: 5000 | AN5: 5000 | AO5: 5000 | AP5: 5000 | AQ5: 10000 | AR5: 15000 | AS5: 15000 | AU5: Auto Transfer to Reserves | AV5: 5000 | AW5: 5000 | AX5: 5000 | AY5: 5000 | AZ5: 5000 | BA5: 5000 | BB5: 5000 | BC5: 5000 | BD5: 10000 | BE5: 10000 | BF5: 10000 | BG5: 5000 | BI5: Auto Transfer to Reserves | BJ5: 5000 | BK5: 5000 | BL5: 5000 | BM5: 5000 | BN5: 5000 | BO5: 5000 | BP5: 5000 | BQ5: 5000 | BR5: 5000 | BS5: 5000 | BT5: 5000 | BU5: 5000 | BW5: Auto Transfer to Reserves | BX5: 60000 | BY5: 60000 | BZ5: 60000 | CA5: 60000 | CB5: 60000 | CC5: 60000 | CD5: 60000 | CE5: 60000 | CF5: 60000 | CG5: 60000 | CH5: 60000 | CI5: 60000 | CJ5: 60000 | CK5: 60000 | CL5: 60000 | CM5: 60000 | CN5: 60000 | CO5: 60000 | CP5: 60000 | CQ5: 60000 | CR5: 60000 | CS5: 60000 | CT5: 60000 | CU5: 60000 | CV5: 60000 | CW5: 60000 | CX5: 60000
A6: Transfer to Operating | K6: 200000 | M6: 50000 | Q6: Transfer to Operating | W6: 150000 | X6: 80000 | Y6: 80000 | Z6: 80000 | AA6: 90000 | AG6: Transfer to Operating | AM6: 100000 | AN6: 50000 | AU6: Transfer to Operating | AZ6: 80000 | BI6: Transfer to Operating | BW6: Transfer to Operating | BX6: 130000 | CD6: 100000
A7: Reserves Account (savings) | B7: 227639 | C7: 232649 | D7: 488667 | E7: =sum(D7+D5-D6) -> 543667 | F7: =sum(E7+E5-E6) -> 599667 | G7: =sum(F7+F5-F6) -> 604667 | H7: 635609 | I7: 516305 | J7: 521158 | K7: =sum(J7+J5-J6) -> 526158 | L7: 533568 | M7: 399381 | Q7: Reserves Account (Money Mkt Accts #3731 & #0598) | R7: 405061 | S7: 410716 | T7: 416309 | U7: =sum(T7+T5-T6) -> 421309 | V7: 522040 | W7: =sum(V7+V5-V6) -> 527040 | X7: =sum(W7+W5-W6) -> 382040 | Y7: =sum(X7+X5-X6) -> 307040 | Z7: =sum(Y7+Y5-Y6) -> 232040 | AA7: =sum(Z7+Z5-Z6) -> 157040 | AB7: =sum(AA7+AA5-AA6) -> 72040 | AC7: =sum(AB7+AB5-AB6) -> 77040 | AG7: Reserves Account (savings) | AH7: =sum(AC7+AC5-AC6) -> 82040 | AI7: =sum(AH7+AH5-AH6) -> 87040 | AJ7: =sum(AI7+AI5+AI8-AI6) -> 220551 | AK7: =sum(AJ7+AJ5-AJ6) -> 225551 | AL7: =sum(AK7+AK5-AK6) -> 230551 | AM7: =sum(AL7+AL5-AL6) -> 235551 | AN7: =sum(AM7+AM5-AM6) -> 140551 | AO7: =sum(AN7+AN5-AN6) -> 95551 | AP7: =sum(AO7+AO5-AO6) -> 100551 | AQ7: =sum(AP7+AP5-AP6) -> 105551 | AR7: =sum(AQ7+AQ5-AQ6) -> 115551 | AS7: =sum(AR7+AR5-AR6) -> 130551 | AU7: Reserves Account (savings) | AV7: =sum(AS7+AS5-AS6) -> 145551 | AW7: =sum(AV7+AV5-AV6) -> 150551 | AX7: =sum(AW7+AW5-AW6) -> 155551 | AY7: =sum(AX7+AX5-AX6) -> 160551 | AZ7: =sum(AY7+AY5-AY6) -> 165551 | BA7: =sum(AZ7+AZ5-AZ6) -> 90551 | BB7: =sum(BA7+BA5-BA6) -> 95551 | BC7: =sum(BB7+BB5-BB6) -> 100551 | BD7: =sum(BC7+BC5-BC6) -> 105551 | ... BG7: =sum(BF7+BF5-BF6) -> 135551 | BI7: Reserves Account (savings) | BJ7: =sum(BG7+BG5-BG6) -> 140551 | BK7: =sum(BJ7+BJ5-BJ6) -> 145551 | BL7: =sum(BK7+BK5-BK6) -> 150551 | BM7: =sum(BL7+BL5-BL6) -> 155551 | BN7: =sum(BM7+BM5-BM6) -> 160551 | BO7: =sum(BN7+BN5-BN6) -> 165551 | BP7: =sum(BO7+BO5-BO6) -> 170551 | BQ7: =sum(BP7+BP5-BP6) -> 175551 | BR7: =sum(BQ7+BQ5-BQ6) -> 180551 | ... BU7: =sum(BT7+BT5-BT6) -> 195551 | BW7: Reserves Account (savings) | BX7: =sum(BU7+BU5-BU6) -> 200551 | BY7: =sum(BX7+BX5-BX6) -> 130551 | BZ7: =sum(BY7+BY5-BY6) -> 190551 | CA7: =sum(BZ7+BZ5-BZ6) -> 250551 | CB7: =sum(CA7+CA5-CA6) -> 310551 | CC7: =sum(CB7+CB5-CB6) -> 370551 | CD7: =sum(CC7+CC5-CC6) -> 430551 | CE7: =sum(CD7+CD5-CD6) -> 390551 | CF7: =sum(CE7+CE5-CE6) -> 450551 | ... CX7: =sum(CW7+CW5-CW6) -> 1530551
A8: Investment Account (CD) | B8: 13231 | C8: 13231 | D8: 13231 | E8: 13231 | F8: =E8+((E8*Inflation!$E$11)/12) -> 13255.808 | G8: =F8+((F8*Inflation!$E$11)/12) -> 13280.663 | H8: 125000 | I8: =H8 -> 125000 | J8: =I8 -> 125000 | K8: =J8 -> 125000 | L8: =K8 -> 125000 | M8: =L8 -> 125000 | Q8: Investment Account (Cert of Deposit) | R8: =M8 -> 125000 | S8: =R8 -> 125000 | T8: =S8 -> 125000 | U8: 128511 | V8: 128511 | W8: =V8 -> 128511 | X8: =W8 -> 128511 | Y8: =X8 -> 128511 | Z8: =Y8 -> 128511 | AA8: =Z8 -> 128511 | AB8: =AA8 -> 128511 | AC8: =AB8 -> 128511 | AG8: Investment Account | AH8: =AC8 -> 128511 | AI8: =AH8 -> 128511 | AJ8: 0 | AK8: 0 | AL8: 0 | AM8: 0 | AN8: 0 | AO8: 0 | AP8: 0 | AQ8: 0 | AR8: 0 | AS8: 0 | AU8: Investment Account | AV8: =AS8 -> 0 | AW8: =AV8 -> 0 | AX8: =AW8+((AW8*Inflation!$E$11)/12) -> 0 | AY8: =AX8 -> 0 | AZ8: =AY8 -> 0 | BA8: =AZ8 -> 0 | BB8: =BA8 -> 0 | BC8: =BB8 -> 0 | BD8: =BC8 -> 0 | BE8: =BD8 -> 0 | BF8: =BE8 -> 0 | BG8: =BF8 -> 0 | BI8: Investment Account | BJ8: =BG8 -> 0 | BK8: =BJ8 -> 0 | BL8: =BK8+((BK8*Inflation!$E$11)/12) -> 0 | BM8: =BL8 -> 0 | BN8: =BM8 -> 0 | BO8: =BN8 -> 0 | BP8: =BO8 -> 0 | BQ8: =BP8 -> 0 | BR8: =BQ8 -> 0 | BS8: =BR8 -> 0 | BT8: =BS8 -> 0 | BU8: =BT8 -> 0 | BW8: Investment Account | BX8: =BU8+(BU8*Inflation!$E$11) -> 0 | BY8: =BX8+((BX8*Inflation!$E$11)) -> 0 | BZ8: =BY8+((BY8*Inflation!$E$11)) -> 0 | CA8: =BZ8+((BZ8*Inflation!$E$11)) -> 0 | CB8: =CA8+((CA8*Inflation!$E$11)) -> 0 | CC8: =CB8+((CB8*Inflation!$E$11)) -> 0 | CD8: =CC8+((CC8*Inflation!$E$11)) -> 0 | CE8: =CD8+((CD8*Inflation!$E$11)) -> 0 | CF8: =CE8+((CE8*Inflation!$E$11)) -> 0 | ... CX8: =CW8+((CW8*Inflation!$E$11)) -> 0
A9: Starting Balance (Current Reserves) | B9: =sum(B4,B7,B8) -> 363814 | C9: =sum(C4,C7,C8) -> 543820 | D9: =sum(D4,D7,D8) -> 618773 | E9: =sum(E4,E7,E8) -> 649719 | F9: =sum(F4,F7,F8) -> 712031.81 | G9: =sum(G4,G7,G8) -> 776459.66 | H9: =sum(H4,H7,H8) -> 963606 | I9: =sum(I4,I7,I8) -> 706386 | ... M9: =sum(M4,M7,M8) -> 610878 | Q9: Starting Balance (Current Reserves) | R9: =sum(R4,R7,R8) -> 607915.91 | S9: =sum(S4,S7,S8) -> 660612.59 | T9: =sum(T4,T7,T8) -> 693379 | U9: =sum(U4,U7,U8) -> 710937.56 | V9: =sum(V4,V7,V8) -> 764102 | W9: =sum(W4,W7,W8) -> 772746.81 | X9: =sum(X4,X7,X8) -> 600165.62 | Y9: =sum(Y4,Y7,Y8) -> 503826.78 | ... AC9: =sum(AC4,AC7,AC8) -> 252728.16 | AG9: Starting Balance (Current Reserves) | AH9: =sum(AH4,AH7,AH8) -> 268775.72 | AI9: =sum(AI4,AI7,AI8) -> 285176.35 | AJ9: =sum(AJ4,AJ7,AJ8) -> 302497.02 | AK9: =sum(AK4,AK7,AK8) -> 317834.93 | AL9: =sum(AL4,AL7,AL8) -> 312331.09 | AM9: =sum(AM4,AM7,AM8) -> 299539.11 | AN9: =sum(AN4,AN7,AN8) -> 162806.73 | AO9: =sum(AO4,AO7,AO8) -> 134884.95 | ... AS9: =sum(AS4,AS7,AS8) -> 211017.86 | AU9: Starting Balance (Current Reserves) | AV9: =sum(AV4,AV7,AV8) -> 228405.76 | AW9: =sum(AW4,AW7,AW8) -> 249979.74 | AX9: =sum(AX4,AX7,AX8) -> 272471.76 | AY9: =sum(AY4,AY7,AY8) -> 292931.44 | AZ9: =sum(AZ4,AZ7,AZ8) -> 304853.84 | BA9: =sum(BA4,BA7,BA8) -> 178382.75 | BB9: =sum(BB4,BB7,BB8) -> 203988.31 | BC9: =sum(BC4,BC7,BC8) -> 229593.88 | ... BG9: =sum(BG4,BG7,BG8) -> 327748.65 | BI9: Starting Balance (Current Reserves) | BJ9: =sum(BJ4,BJ7,BJ8) -> 350309.58 | BK9: =sum(BK4,BK7,BK8) -> 363191.65 | BL9: =sum(BL4,BL7,BL8) -> 376989.72 | BM9: =sum(BM4,BM7,BM8) -> 388704.63 | BN9: =sum(BN4,BN7,BN8) -> 391852.36 | BO9: =sum(BO4,BO7,BO8) -> 409131.64 | BP9: =sum(BP4,BP7,BP8) -> 426410.91 | BQ9: =sum(BQ4,BQ7,BQ8) -> 443690.18 | ... BU9: =sum(BU4,BU7,BU8) -> 514000.82 | BW9: Starting Balance (Current Reserves) | BX9: =sum(BX4,BX7,BX8) -> 527869.51 | BY9: =sum(BY4,BY7,BY8) -> 686202.63 | BZ9: =sum(BZ4,BZ7,BZ8) -> 951900.25 | CA9: =sum(CA4,CA7,CA8) -> 1077903.8 | CB9: =sum(CB4,CB7,CB8) -> 1309219.9 | CC9: =sum(CC4,CC7,CC8) -> 1522556 | CD9: =sum(CD4,CD7,CD8) -> 1163888.6 | CE9: =sum(CE4,CE7,CE8) -> 927245.83 | ... CX9: =sum(CX4,CX7,CX8) -> 1661161
A10: CASH IN | Q10: CASH IN | AG10: CASH IN | AU10: CASH IN | BI10: CASH IN | BW10: CASH IN
A11: Interest Income | B11: 10 | C11: 18 | D11: 23 | E11: 25 | F11: 26 | G11: 24 | H11: 686 | I11: =I7*(Inflation!$E$11)/12 -> 968.07187 | J11: 1119 | K11: 637 | L11: 814 | M11: =M7*(Inflation!$E$11)/12 -> 748.83938 | N11: =SUM(B11:M11) -> 5098.9113 | O11: 4008 | P11: =N11-O11 -> 1090.9113 | Q11: Interest Income | R11: 655 | S11: 592 | T11: =(T7*(Inflation!$F$11)/12)+3751 -> 4444.8483 | U11: =U7*(Inflation!$F$11)/12 -> 702.18167 | V11: =V7*(Inflation!$F$11)/12 -> 870.06667 | W11: =W7*(Inflation!$F$11)/12 -> 878.4 | X11: =X7*(Inflation!$F$11)/12 -> 636.73333 | Y11: =Y7*(Inflation!$F$11)/12 -> 511.73333 | Z11: =Z7*(Inflation!$F$11)/12 -> 386.73333 | AA11: =AA7*(Inflation!$F$11)/12 -> 261.73333 | AB11: =AB7*(Inflation!$F$11)/12 -> 120.06667 | AC11: =AC7*(Inflation!$F$11)/12 -> 128.4 | AD11: =SUM(R11:AC11) -> 10187.897 | AE11: 5300 | AF11: =AD11-AE11 -> 4887.8967 | AG11: Interest Income | AH11: =AH7*(Inflation!$F$11)/12 -> 136.73333 | AI11: =AI7*(Inflation!$F$11)/12 -> 145.06667 | AJ11: =AJ7*(Inflation!$G$11)/12 -> 367.585 | AK11: =AK7*(Inflation!$G$11)/12 -> 375.91833 | AL11: =AL7*(Inflation!$G$11)/12 -> 384.25167 | AM11: =AM7*(Inflation!$G$11)/12 -> 392.585 | AN11: =AN7*(Inflation!$G$11)/12 -> 234.25167 | AO11: =AO7*(Inflation!$G$11)/12 -> 159.25167 | AP11: =AP7*(Inflation!$G$11)/12 -> 167.585 | AQ11: =AQ7*(Inflation!$G$11)/12 -> 175.91833 | ... AS11: =AS7*(Inflation!$G$11)/12 -> 217.585 | AT11: =SUM(AH11:AS11) -> 2949.3167 | AU11: Interest Income | AV11: =AV7*(Inflation!$G$11)/12 -> 242.585 | AW11: =AW7*(Inflation!$G$11)/12 -> 250.91833 | AX11: =AX7*(Inflation!$H$11)/12 -> 259.25167 | AY11: =AY7*(Inflation!$H$11)/12 -> 267.585 | AZ11: =AZ7*(Inflation!$H$11)/12 -> 275.91833 | BA11: =BA7*(Inflation!$H$11)/12 -> 150.91833 | BB11: =BB7*(Inflation!$H$11)/12 -> 159.25167 | BC11: =BC7*(Inflation!$H$11)/12 -> 167.585 | BD11: =BD7*(Inflation!$H$11)/12 -> 175.91833 | BE11: =BE7*(Inflation!$H$11)/12 -> 192.585 | ... BG11: =BG7*(Inflation!$H$11)/12 -> 225.91833 | BH11: =SUM(AV11:BG11) -> 2577.6867 | BI11: Interest Income | BJ11: =BJ7*(Inflation!$H$11)/12 -> 234.25167 | BK11: =BK7*(Inflation!$H$11)/12 -> 242.585 | BL11: =BL7*(Inflation!$I$11)/12 -> 250.91833 | BM11: =BM7*(Inflation!$I$11)/12 -> 259.25167 | BN11: =BN7*(Inflation!$I$11)/12 -> 267.585 | BO11: =BO7*(Inflation!$I$11)/12 -> 275.91833 | BP11: =BP7*(Inflation!$I$11)/12 -> 284.25167 | BQ11: =BQ7*(Inflation!$I$11)/12 -> 292.585 | BR11: =BR7*(Inflation!$I$11)/12 -> 300.91833 | BS11: =BS7*(Inflation!$I$11)/12 -> 309.25167 | ... BU11: =BU7*(Inflation!$I$11)/12 -> 325.91833 | BV11: =SUM(BJ11:BU11) -> 3361.02 | BW11: Interest Income | BX11: =BX7*(Inflation!$J$11)/12 -> 334.25167 | BY11: =BY7*(Inflation!$J$11)/12 -> 217.585 | BZ11: =BZ7*(Inflation!$J$11)/12 -> 317.585 | CA11: =CA7*(Inflation!$J$11)/12 -> 417.585 | CB11: =CB7*(Inflation!$J$11)/12 -> 517.585 | CC11: =CC7*(Inflation!$J$11)/12 -> 617.585 | CD11: =CD7*(Inflation!$J$11)/12 -> 717.585 | CE11: =CE7*(Inflation!$J$11)/12 -> 650.91833 | ... CX11: =CX7*(Inflation!$J$11)/12 -> 2550.9183
A12: Income from Owner Assessments | B12: 254010 | C12: 98880 | D12: 101008 | E12: 92733 | F12: 83435 | G12: 88100 | H12: 85296 | I12: 86668 | J12: 81555 | K12: 97010 | L12: 84290 | M12: 86668 | N12: =SUM(B12:M12) -> 1239653 | O12: 1324800 | P12: =60000+N12-O12 -> -25147 | Q12: Income from Owner Assessments | R12: 78325 | S12: 65716 | T12: =($AE$12-($R12+$S12))/($AC$1-$S1) -> 55975.9 | U12: =($AE$12-($R12+$S12))/($AC$1-$S1) -> 55975.9 | V12: =($AE$12-($R12+$S12))/($AC$1-$S1) -> 55975.9 | W12: =($AE$12-($R12+$S12))/($AC$1-$S1) -> 55975.9 | X12: =($AE$12-($R12+$S12))/($AC$1-$S1) -> 55975.9 | Y12: =($AE$12-($R12+$S12))/($AC$1-$S1) -> 55975.9 | Z12: =($AE$12-($R12+$S12))/($AC$1-$S1) -> 55975.9 | AA12: =($AE$12-($R12+$S12))/($AC$1-$S1) -> 55975.9 | ... AC12: =($AE$12-($R12+$S12))/($AC$1-$S1) -> 55975.9 | AD12: =SUM(R12:AC12) -> 703800 | AE12: 703800 | AF12: =AD12-AE12 -> 1.1641532e-10 | AG12: Income from Owner Assessments | AH12: =138*(AH49+AH48) -> 58650 | AI12: =138*(AI49+AI48) -> 58650 | AJ12: =138*(AJ49+AJ48) -> 58650 | AK12: =138*(AK49+AK48) -> 58650 | AL12: =138*(AL49+AL48) -> 58650 | AM12: =138*(AM49+AM48) -> 58650 | AN12: =138*(AN49+AN48) -> 58650 | AO12: =138*(AO49+AO48) -> 58650 | ... AS12: =138*(AS49+AS48) -> 58650 | AT12: =SUM(AH12:AS12) -> 703800 | AU12: Income from Owner Assessments | AV12: =138*(AV49+AV48) -> 65550 | AW12: =138*(AW49+AW48) -> 65550 | AX12: =138*(AX49+AX48) -> 65550 | AY12: =138*(AY49+AY48) -> 65550 | AZ12: =138*(AZ49+AZ48) -> 65550 | BA12: =138*(BA49+BA48) -> 65550 | BB12: =138*(BB49+BB48) -> 65550 | BC12: =138*(BC49+BC48) -> 65550 | ... BG12: =138*(BG49+BG48) -> 65550 | BH12: =SUM(AV12:BG12) -> 786600 | BI12: Income from Owner Assessments | BJ12: =138*(BJ49+BJ48) -> 58650 | BK12: =138*(BK49+BK48) -> 58650 | BL12: =138*(BL49+BL48) -> 58650 | BM12: =138*(BM49+BM48) -> 58650 | BN12: =138*(BN49+BN48) -> 58650 | BO12: =138*(BO49+BO48) -> 58650 | BP12: =138*(BP49+BP48) -> 58650 | BQ12: =138*(BQ49+BQ48) -> 58650 | ... BU12: =138*(BU49+BU48) -> 58650 | BV12: =SUM(BJ12:BU12) -> 703800 | BW12: Income from Owner Assessments | BX12: =138*(BX48+BX49)*12 -> 703800 | BY12: =138*(BY48+BY49)*12 -> 828000 | BZ12: =138*(BZ48+BZ49)*12 -> 828000 | CA12: =138*(CA48+CA49)*12 -> 828000 | CB12: =138*(CB48+CB49)*12 -> 828000 | CC12: =138*(CC48+CC49)*12 -> 828000 | CD12: =138*(CD48+CD49)*12 -> 952200 | CE12: =138*(CE48+CE49)*12 -> 952200 | ... CX12: =138*(CX48+CX49)*12 -> 1407600
A13: Other Income Apt Rent | B13: 0 | C13: 0 | D13: 2500 | E13: 2500 | F13: 2500 | G13: 2500 | H13: 2500 | I13: 2500 | J13: 2500 | K13: 2500 | L13: 2500 | M13: 2500 | N13: =SUM(B13:M13) -> 25000 | O13: 30000 | P13: =N13-O13 -> -5000 | Q13: Other Income Apt Rent | R13: 2500 | S13: =R13 -> 2500 | T13: =S13 -> 2500 | U13: =T13 -> 2500 | V13: =U13 -> 2500 | W13: =V13 -> 2500 | X13: =W13 -> 2500 | Y13: =X13 -> 2500 | Z13: =Y13 -> 2500 | ... AC13: =AB13 -> 2500 | AD13: =SUM(R13:AC13) -> 30000 | AE13: 30000 | AF13: =AD13-AE13 -> 0 | AG13: Other Income Apt Rent | AH13: =AC13*(1+(Inflation!$F$6)) -> 2562.5 | AI13: =AH13 -> 2562.5 | AJ13: =AI13 -> 2562.5 | AK13: =AJ13 -> 2562.5 | AL13: =AK13 -> 2562.5 | AM13: =AL13 -> 2562.5 | AN13: =AM13 -> 2562.5 | AO13: =AN13 -> 2562.5 | AP13: =AO13 -> 2562.5 | ... AS13: =AR13 -> 2562.5 | AT13: =SUM(AH13:AS13) -> 30750 | AU13: Other Income Apt Rent | AV13: =AS13*(1+(Inflation!$F$6)) -> 2626.5625 | AW13: =AV13 -> 2626.5625 | AX13: =AW13 -> 2626.5625 | AY13: =AX13 -> 2626.5625 | AZ13: =AY13 -> 2626.5625 | BA13: =AZ13 -> 2626.5625 | BB13: =BA13 -> 2626.5625 | BC13: =BB13 -> 2626.5625 | BD13: =BC13 -> 2626.5625 | ... BG13: =BF13 -> 2626.5625 | BH13: =SUM(AV13:BG13) -> 31518.75 | BI13: Other Income Apt Rent | BJ13: =BG13*(1+(Inflation!$F$6)) -> 2692.2266 | BK13: =BJ13 -> 2692.2266 | BL13: =BK13 -> 2692.2266 | BM13: =BL13 -> 2692.2266 | BN13: =BM13 -> 2692.2266 | BO13: =BN13 -> 2692.2266 | BP13: =BO13 -> 2692.2266 | BQ13: =BP13 -> 2692.2266 | BR13: =BQ13 -> 2692.2266 | ... BU13: =BT13 -> 2692.2266 | BV13: =SUM(BJ13:BU13) -> 32306.719 | BW13: Other Income Apt Rent | BX13: =BV13*(1+Inflation!$I$5) -> 33114.387 | BY13: =BX13*(1+Inflation!$I$5) -> 33942.246 | BZ13: =BY13*(1+Inflation!$I$5) -> 34790.803 | CA13: =BZ13*(1+Inflation!$I$5) -> 35660.573 | CB13: =CA13*(1+Inflation!$I$5) -> 36552.087 | CC13: =CB13*(1+Inflation!$I$5) -> 37465.889 | CD13: =CC13*(1+Inflation!$I$5) -> 38402.536 | CE13: =CD13*(1+Inflation!$I$5) -> 39362.6 | CF13: =CE13*(1+Inflation!$I$5) -> 40346.665 | ... CX13: =CW13*(1+Inflation!$I$5) -> 62927.027
A14: RV Park Fees | B14: 0 | C14: 0 | D14: 0 | E14: 0 | F14: 0 | G14: 0 | H14: 0 | I14: 0 | J14: 0 | K14: 0 | L14: 0 | M14: 0 | N14: =SUM(B14:M14) -> 0 | O14: 2100 | P14: =N14-O14 -> -2100 | Q14: RV Park Fees | R14: 175 | S14: =R14 -> 175 | T14: =S14 -> 175 | U14: =T14 -> 175 | V14: =U14 -> 175 | W14: =V14 -> 175 | X14: =W14 -> 175 | Y14: =X14 -> 175 | Z14: =Y14 -> 175 | ... AC14: =AB14 -> 175 | AD14: =SUM(R14:AC14) -> 2100 | AE14: 2100 | AF14: =AD14-AE14 -> 0 | AG14: RV Park Fees | AH14: =AC14*(1+(Inflation!$F$6)) -> 179.375 | AI14: =AH14 -> 179.375 | AJ14: =AI14 -> 179.375 | AK14: =AJ14 -> 179.375 | AL14: =AK14 -> 179.375 | AM14: =AL14 -> 179.375 | AN14: =AM14 -> 179.375 | AO14: =AN14 -> 179.375 | AP14: =AO14 -> 179.375 | ... AS14: =AR14 -> 179.375 | AT14: =SUM(AH14:AS14) -> 2152.5 | AU14: RV Park Fees | AV14: =AS14*(1+(Inflation!$F$6)) -> 183.85938 | AW14: =AV14 -> 183.85938 | AX14: =AW14 -> 183.85938 | AY14: =AX14 -> 183.85938 | AZ14: =AY14 -> 183.85938 | BA14: =AZ14 -> 183.85938 | BB14: =BA14 -> 183.85938 | BC14: =BB14 -> 183.85938 | BD14: =BC14 -> 183.85938 | ... BG14: =BF14 -> 183.85938 | BH14: =SUM(AV14:BG14) -> 2206.3125 | BI14: RV Park Fees | BJ14: =BG14*(1+(Inflation!$F$6)) -> 188.45586 | BK14: =BJ14 -> 188.45586 | BL14: =BK14 -> 188.45586 | BM14: =BL14 -> 188.45586 | BN14: =BM14 -> 188.45586 | BO14: =BN14 -> 188.45586 | BP14: =BO14 -> 188.45586 | BQ14: =BP14 -> 188.45586 | BR14: =BQ14 -> 188.45586 | ... BU14: =BT14 -> 188.45586 | BV14: =SUM(BJ14:BU14) -> 2261.4703 | BW14: RV Park Fees | BX14: =BV14*(1+Inflation!$I$5) -> 2318.0071 | BY14: =BX14*(1+Inflation!$I$5) -> 2375.9572 | BZ14: =BY14*(1+Inflation!$I$5) -> 2435.3562 | CA14: =BZ14*(1+Inflation!$I$5) -> 2496.2401 | CB14: =CA14*(1+Inflation!$I$5) -> 2558.6461 | CC14: =CB14*(1+Inflation!$I$5) -> 2622.6122 | CD14: =CC14*(1+Inflation!$I$5) -> 2688.1775 | CE14: =CD14*(1+Inflation!$I$5) -> 2755.382 | CF14: =CE14*(1+Inflation!$I$5) -> 2824.2665 | ... CX14: =CW14*(1+Inflation!$I$5) -> 4404.8919
A15: Late Fees, Resale Certificates | B15: 0 | C15: 0 | D15: 0 | E15: 0 | F15: 0 | G15: 0 | H15: 71 | I15: 0 | J15: 0 | K15: 0 | L15: 0 | M15: 0 | N15: =SUM(B15:M15) -> 71 | P15: =N15-O15 -> 71 | Q15: Late Fees, Resale Certificates | R15: =M15*(1+(Inflation!$F$6)) -> 0 | S15: =R15 -> 0 | T15: =S15 -> 0 | U15: =T15 -> 0 | V15: =U15 -> 0 | W15: =V15 -> 0 | X15: =W15 -> 0 | Y15: =X15 -> 0 | Z15: =Y15 -> 0 | ... AB15: =AA15 -> 0 | AC15: 0 | AD15: =SUM(R15:AC15) -> 0 | AE15: 0 | AF15: =AD15-AE15 -> 0 | AG15: Late Fees, Resale Certificates | AH15: =AC15*(1+(Inflation!$F$6)) -> 0 | AI15: =AH15 -> 0 | AT15: =SUM(AH15:AS15) -> 0 | AU15: Late Fees, Resale Certificates | AV15: =AS15*(1+(Inflation!$F$6)) -> 0 | AW15: =AV15 -> 0 | AX15: =AW15 -> 0 | AY15: =AX15 -> 0 | AZ15: =AY15 -> 0 | BA15: =AZ15 -> 0 | BB15: =BA15 -> 0 | BC15: =BB15 -> 0 | BD15: =BC15 -> 0 | ... BG15: =BF15 -> 0 | BH15: =SUM(AV15:BG15) -> 0 | BI15: Late Fees, Resale Certificates | BJ15: =BG15*(1+(Inflation!$F$6)) -> 0 | BK15: =BJ15 -> 0 | BL15: =BK15 -> 0 | BM15: =BL15 -> 0 | BN15: =BM15 -> 0 | BO15: =BN15 -> 0 | BP15: =BO15 -> 0 | BQ15: =BP15 -> 0 | BR15: =BQ15 -> 0 | ... BU15: =BT15 -> 0 | BV15: =SUM(BJ15:BU15) -> 0 | BW15: Late Fees, Resale Certificates | BX15: =BV15*(1+Inflation!$I$5) -> 0 | BY15: =BX15*(1+Inflation!$I$5) -> 0 | BZ15: =BY15*(1+Inflation!$I$5) -> 0 | CA15: =BZ15*(1+Inflation!$I$5) -> 0 | CB15: =CA15*(1+Inflation!$I$5) -> 0 | CC15: =CB15*(1+Inflation!$I$5) -> 0 | CD15: =CC15*(1+Inflation!$I$5) -> 0 | CE15: =CD15*(1+Inflation!$I$5) -> 0 | CF15: =CE15*(1+Inflation!$I$5) -> 0 | ... CX15: =CW15*(1+Inflation!$I$5) -> 0
A16: TOTAL CASH IN | B16: =SUM(B11:B15) -> 254020 | C16: =SUM(C11:C15) -> 98898 | D16: =SUM(D11:D15) -> 103531 | E16: =SUM(E11:E15) -> 95258 | F16: =SUM(F11:F15) -> 85961 | G16: =SUM(G11:G15) -> 90624 | H16: =SUM(H11:H15) -> 88553 | I16: =SUM(I11:I15) -> 90136.072 | ... M16: =SUM(M11:M15) -> 89916.839 | N16: =SUM(B16:M16) -> 1269822.9 | O16: =SUM(O11:O15) -> 1360908 | P16: =SUM(P12:P15) -> -32176 | Q16: TOTAL CASH IN | R16: =SUM(R11:R15)-R11 -> 81000 | S16: =SUM(S11:S15)-S11 -> 68391 | T16: =SUM(T11:T15)-T11 -> 58650.9 | U16: =SUM(U11:U15)-U11 -> 58650.9 | V16: =SUM(V11:V15)-V11 -> 58650.9 | W16: =SUM(W11:W15)-W11 -> 58650.9 | X16: =SUM(X11:X15)-X11 -> 58650.9 | Y16: =SUM(Y11:Y15)-Y11 -> 58650.9 | ... AC16: =SUM(AC11:AC15)-AC11 -> 58650.9 | AD16: =SUM(R16:AC16) -> 735900 | AE16: =SUM(AE11:AE15) -> 741200 | AG16: TOTAL CASH IN | AH16: =SUM(AH11:AH15)-AH11 -> 61391.875 | AI16: =SUM(AI11:AI15)-AI11 -> 61391.875 | AJ16: =SUM(AJ11:AJ15)-AJ11 -> 61391.875 | AK16: =SUM(AK11:AK15)-AK11 -> 61391.875 | AL16: =SUM(AL11:AL15)-AL11 -> 61391.875 | AM16: =SUM(AM11:AM15)-AM11 -> 61391.875 | AN16: =SUM(AN11:AN15)-AN11 -> 61391.875 | AO16: =SUM(AO11:AO15)-AO11 -> 61391.875 | ... AS16: =SUM(AS11:AS15)-AS11 -> 61391.875 | AT16: =SUM(AH16:AS16) -> 736702.5 | AU16: TOTAL CASH IN | AV16: =SUM(AV11:AV15)-AV11 -> 68360.422 | AW16: =SUM(AW11:AW15)-AW11 -> 68360.422 | AX16: =SUM(AX11:AX15)-AX11 -> 68360.422 | AY16: =SUM(AY11:AY15)-AY11 -> 68360.422 | AZ16: =SUM(AZ11:AZ15)-AZ11 -> 68360.422 | BA16: =SUM(BA11:BA15)-BA11 -> 68360.422 | BB16: =SUM(BB11:BB15)-BB11 -> 68360.422 | BC16: =SUM(BC11:BC15)-BC11 -> 68360.422 | ... BG16: =SUM(BG11:BG15)-BG11 -> 68360.422 | BH16: =SUM(AV16:BG16) -> 820325.06 | BI16: TOTAL CASH IN | BJ16: =SUM(BJ11:BJ15)-BJ11 -> 61530.682 | BK16: =SUM(BK11:BK15)-BK11 -> 61530.682 | BL16: =SUM(BL11:BL15)-BL11 -> 61530.682 | BM16: =SUM(BM11:BM15)-BM11 -> 61530.682 | BN16: =SUM(BN11:BN15)-BN11 -> 61530.682 | BO16: =SUM(BO11:BO15)-BO11 -> 61530.682 | BP16: =SUM(BP11:BP15)-BP11 -> 61530.682 | BQ16: =SUM(BQ11:BQ15)-BQ11 -> 61530.682 | ... BU16: =SUM(BU11:BU15)-BU11 -> 61530.682 | BV16: =SUM(BJ16:BU16) -> 738368.19 | BW16: TOTAL CASH IN | BX16: =SUM(BX11:BX15)-BX11 -> 739232.39 | BY16: =SUM(BY11:BY15)-BY11 -> 864318.2 | BZ16: =SUM(BZ11:BZ15)-BZ11 -> 865226.16 | CA16: =SUM(CA11:CA15)-CA11 -> 866156.81 | CB16: =SUM(CB11:CB15)-CB11 -> 867110.73 | CC16: =SUM(CC11:CC15)-CC11 -> 868088.5 | CD16: =SUM(CD11:CD15)-CD11 -> 993290.71 | CE16: =SUM(CE11:CE15)-CE11 -> 994317.98 | ... CX16: =SUM(CX11:CX15)-CX11 -> 1474931.9
A17: CASH OUT | Q17: CASH OUT | AG17: CASH OUT | AU17: CASH OUT | BI17: CASH OUT | BW17: CASH OUT
A18: Financial Management | Q18: Financial Management | AG18: Financial Management | AU18: Financial Management | BI18: Financial Management | BW18: Financial Management
A19: Accounting | B19: 402 | C19: 402 | D19: 1602 | E19: 0 | F19: 402 | G19: 402 | H19: 402 | I19: 401 | J19: 535 | K19: 535 | L19: 703 | M19: 704 | N19: =SUM(B19:M19) -> 6490 | O19: 8437 | P19: =N19-O19 -> -1947 | Q19: Accounting + PayHOA Svc | R19: 0 | S19: 142 | T19: 554 | U19: =T19 -> 554 | V19: =U19 -> 554 | W19: =V19 -> 554 | X19: =W19 -> 554 | Y19: =X19 -> 554 | Z19: =Y19 -> 554 | AA19: =Z19 -> 554 | AB19: =AA19 -> 554 | AC19: =AB19 -> 554 | AD19: =SUM(R19:AC19) -> 5682 | AE19: 6824 | AF19: =AD19-AE19 -> -1142 | AG19: Accounting | AH19: =(AD19/12)*(1+(Inflation!$G$6)) -> 485.3375 | AI19: =AH19 -> 485.3375 | AJ19: =AI19 -> 485.3375 | AK19: =AJ19 -> 485.3375 | AL19: =AK19 -> 485.3375 | AM19: =AL19 -> 485.3375 | AN19: =AM19 -> 485.3375 | AO19: =AN19 -> 485.3375 | AP19: =AO19 -> 485.3375 | ... AS19: =AR19 -> 485.3375 | AT19: =SUM(AH19:AS19) -> 5824.05 | AU19: Accounting | AV19: =(AT19/12)*(1+(Inflation!$H$6)) -> 497.47094 | AW19: =AV19 -> 497.47094 | AX19: =AW19 -> 497.47094 | AY19: =AX19 -> 497.47094 | AZ19: =AY19 -> 497.47094 | BA19: =AZ19 -> 497.47094 | BB19: =BA19 -> 497.47094 | BC19: =BB19 -> 497.47094 | BD19: =BC19 -> 497.47094 | ... BG19: =BF19 -> 497.47094 | BH19: =SUM(AV19:BG19) -> 5969.6512 | BI19: Accounting | BJ19: =(BH19/12)*(1+(Inflation!$I$6)) -> 509.90771 | BK19: =BJ19 -> 509.90771 | BL19: =BK19 -> 509.90771 | BM19: =BL19 -> 509.90771 | BN19: =BM19 -> 509.90771 | BO19: =BN19 -> 509.90771 | BP19: =BO19 -> 509.90771 | BQ19: =BP19 -> 509.90771 | BR19: =BQ19 -> 509.90771 | ... BU19: =BT19 -> 509.90771 | BV19: =SUM(BJ19:BU19) -> 6118.8925 | BW19: Accounting | BX19: =BV19*(1+Inflation!$J$5) -> 6271.8648 | BY19: =BX19*(1+Inflation!$J$5) -> 6428.6615 | BZ19: =BY19*(1+Inflation!$J$5) -> 6589.378 | CA19: =BZ19*(1+Inflation!$J$5) -> 6754.1125 | CB19: =CA19*(1+Inflation!$J$5) -> 6922.9653 | CC19: =CB19*(1+Inflation!$J$5) -> 7096.0394 | CD19: =CC19*(1+Inflation!$J$5) -> 7273.4404 | CE19: =CD19*(1+Inflation!$J$5) -> 7455.2764 | CF19: =CE19*(1+Inflation!$J$5) -> 7641.6583 | ... CX19: =CW19*(1+Inflation!$J$5) -> 11918.379
A20: Insurance | B20: 4877 | C20: 4877 | D20: 6940 | E20: 4875 | F20: 6977 | G20: 6977 | H20: 6977 | I20: 7430 | J20: 7939 | K20: 7430 | L20: 7458 | M20: 7458 | N20: =SUM(B20:M20) -> 80215 | O20: 66163 | P20: =N20-O20 -> 14052 | Q20: Insurance | R20: 7458 | S20: =R20 -> 7458 | T20: =S20+2000 -> 9458 | U20: =S20 -> 7458 | V20: =U20 -> 7458 | W20: =V20 -> 7458 | X20: =W20 -> 7458 | Y20: =X20 -> 7458 | Z20: =Y20 -> 7458 | AA20: =Z20 -> 7458 | AB20: =AA20 -> 7458 | AC20: =AB20 -> 7458 | AD20: =SUM(R20:AC20) -> 91496 | AE20: 95097 | AF20: =AD20-AE20 -> -3601 | AG20: Insurance | AH20: =AC20*(1+(Inflation!$F$6)) -> 7644.45 | AI20: =AH20 -> 7644.45 | AJ20: =(T20*(1+(Inflation!$F$6))) -> 9694.45 | AK20: =AI20 -> 7644.45 | AL20: =AK20 -> 7644.45 | AM20: =AL20 -> 7644.45 | AN20: =AM20 -> 7644.45 | AO20: =AN20 -> 7644.45 | AP20: =AO20 -> 7644.45 | AQ20: =AP20 -> 7644.45 | AR20: =AQ20 -> 7644.45 | AS20: =AR20 -> 7644.45 | AT20: =SUM(AH20:AS20) -> 93783.4 | AU20: Insurance | AV20: =AS20*(1+(Inflation!$F$6)) -> 7835.5612 | AW20: =AV20 -> 7835.5612 | AX20: =(AJ20*(1+(Inflation!$G$6))) -> 9936.8113 | AY20: =AW20 -> 7835.5612 | AZ20: =AY20 -> 7835.5612 | BA20: =AZ20 -> 7835.5612 | BB20: =BA20 -> 7835.5612 | BC20: =BB20 -> 7835.5612 | BD20: =BC20 -> 7835.5612 | BE20: =BD20 -> 7835.5612 | BF20: =BE20 -> 7835.5612 | BG20: =BF20 -> 7835.5612 | BH20: =SUM(AV20:BG20) -> 96127.985 | BI20: Insurance | BJ20: =BG20*(1+(Inflation!$F$6)) -> 8031.4503 | BK20: =BJ20 -> 8031.4503 | BL20: =(AX20*(1+(Inflation!$H$6))) -> 10185.232 | BM20: =BK20 -> 8031.4503 | BN20: =BM20 -> 8031.4503 | BO20: =BN20 -> 8031.4503 | BP20: =BO20 -> 8031.4503 | BQ20: =BP20 -> 8031.4503 | BR20: =BQ20 -> 8031.4503 | BS20: =BR20 -> 8031.4503 | BT20: =BS20 -> 8031.4503 | BU20: =BT20 -> 8031.4503 | BV20: =SUM(BJ20:BU20) -> 98531.185 | BW20: Insurance | BX20: =BV20*(1+Inflation!$J$5) -> 100994.46 | BY20: =BX20*(1+Inflation!$J$5) -> 103519.33 | BZ20: =BY20*(1+Inflation!$J$5) -> 106107.31 | CA20: =BZ20*(1+Inflation!$J$5) -> 108759.99 | CB20: =CA20*(1+Inflation!$J$5) -> 111478.99 | CC20: =CB20*(1+Inflation!$J$5) -> 114265.97 | CD20: =CC20*(1+Inflation!$J$5) -> 117122.62 | CE20: =CD20*(1+Inflation!$J$5) -> 120050.68 | CF20: =CE20*(1+Inflation!$J$5) -> 123051.95 | ... CX20: =CW20*(1+Inflation!$J$5) -> 191919.04
A21: Legal/Professional Services | B21: 54 | C21: 0 | D21: 0 | E21: 0 | F21: 12 | G21: 0 | H21: 0 | I21: 0 | J21: 0 | K21: 568 | L21: 833 | M21: 837 | N21: =SUM(B21:M21) -> 2304 | O21: 10000 | P21: =N21-O21 -> -7696 | Q21: Legal/Professional Services | R21: =M21*(1+(Inflation!$F$6)) -> 857.925 | S21: =R21 -> 857.925 | T21: =S21 -> 857.925 | U21: =T21 -> 857.925 | V21: =U21 -> 857.925 | W21: =V21 -> 857.925 | X21: =W21 -> 857.925 | Y21: =X21 -> 857.925 | Z21: =Y21 -> 857.925 | ... AC21: =AB21 -> 857.925 | AD21: =SUM(R21:AC21) -> 10295.1 | AE21: 10295 | AF21: =AD21-AE21 -> 0.1 | AG21: Legal/Professional Services | AH21: =R21*(1+(Inflation!$G$6)) -> 879.37312 | AI21: =S21*(1+(Inflation!$G$6)) -> 879.37312 | AJ21: =T21*(1+(Inflation!$G$6)) -> 879.37312 | AK21: =U21*(1+(Inflation!$G$6)) -> 879.37312 | AL21: =V21*(1+(Inflation!$G$6)) -> 879.37312 | AM21: =W21*(1+(Inflation!$G$6)) -> 879.37312 | AN21: =X21*(1+(Inflation!$G$6)) -> 879.37312 | AO21: =Y21*(1+(Inflation!$G$6)) -> 879.37312 | ... AS21: =AC21*(1+(Inflation!$G$6)) -> 879.37312 | AT21: =SUM(AH21:AS21) -> 10552.478 | AU21: Legal/Professional Services | AV21: =AH21*(1+(Inflation!$H$6)) -> 901.35745 | AW21: =AI21*(1+(Inflation!$G$6)) -> 901.35745 | AX21: =AJ21*(1+(Inflation!$H$6)) -> 901.35745 | AY21: =AK21*(1+(Inflation!$G$6)) -> 901.35745 | AZ21: =AL21*(1+(Inflation!$G$6)) -> 901.35745 | BA21: =AM21*(1+(Inflation!$H$6)) -> 901.35745 | BB21: =AN21*(1+(Inflation!$G$6)) -> 901.35745 | BC21: =AO21*(1+(Inflation!$G$6)) -> 901.35745 | BD21: =AP21*(1+(Inflation!$H$6)) -> 901.35745 | BE21: =AQ21*(1+(Inflation!$G$6)) -> 901.35745 | BF21: =AR21*(1+(Inflation!$G$6)) -> 901.35745 | BG21: =AS21*(1+(Inflation!$G$6)) -> 901.35745 | BH21: =SUM(AV21:BG21) -> 10816.289 | BI21: Legal/Professional Services | BJ21: =AV21*(1+(Inflation!$I$6)) -> 923.89139 | BK21: =AW21*(1+(Inflation!$G$6)) -> 923.89139 | BL21: =AX21*(1+(Inflation!$H$6)) -> 923.89139 | BM21: =AY21*(1+(Inflation!$G$6)) -> 923.89139 | BN21: =AZ21*(1+(Inflation!$G$6)) -> 923.89139 | BO21: =BA21*(1+(Inflation!$H$6)) -> 923.89139 | BP21: =BB21*(1+(Inflation!$G$6)) -> 923.89139 | BQ21: =BC21*(1+(Inflation!$G$6)) -> 923.89139 | BR21: =BD21*(1+(Inflation!$H$6)) -> 923.89139 | BS21: =BE21*(1+(Inflation!$G$6)) -> 923.89139 | BT21: =BF21*(1+(Inflation!$G$6)) -> 923.89139 | BU21: =BG21*(1+(Inflation!$G$6)) -> 923.89139 | BV21: =SUM(BJ21:BU21) -> 11086.697 | BW21: Legal/Professional Services | BX21: =BV21*(1+Inflation!$J$5) -> 11363.864 | BY21: =BX21*(1+Inflation!$J$5) -> 11647.961 | BZ21: =BY21*(1+Inflation!$J$5) -> 11939.16 | CA21: =BZ21*(1+Inflation!$J$5) -> 12237.639 | CB21: =CA21*(1+Inflation!$J$5) -> 12543.58 | CC21: =CB21*(1+Inflation!$J$5) -> 12857.169 | CD21: =CC21*(1+Inflation!$J$5) -> 13178.598 | CE21: =CD21*(1+Inflation!$J$5) -> 13508.063 | CF21: =CE21*(1+Inflation!$J$5) -> 13845.765 | ... CX21: =CW21*(1+Inflation!$J$5) -> 21594.668
A22: Subtotal | B22: =SUM(B19:B21) -> 5333 | C22: =SUM(C19:C21) -> 5279 | D22: =SUM(D19:D21) -> 8542 | E22: =SUM(E19:E21) -> 4875 | F22: =SUM(F19:F21) -> 7391 | G22: =SUM(G19:G21) -> 7379 | H22: =SUM(H19:H21) -> 7379 | I22: =SUM(I19:I21) -> 7831 | ... M22: =SUM(M19:M21) -> 8999 | N22: =SUM(B22:M22) -> 89009 | O22: =SUM(O19:O21) -> 84600 | P22: =N22-O22 -> 4409 | Q22: Subtotal | R22: =SUM(R19:R21) -> 8315.925 | S22: =SUM(S19:S21) -> 8457.925 | T22: =SUM(T19:T21) -> 10869.925 | U22: =SUM(U19:U21) -> 8869.925 | V22: =SUM(V19:V21) -> 8869.925 | W22: =SUM(W19:W21) -> 8869.925 | X22: =SUM(X19:X21) -> 8869.925 | Y22: =SUM(Y19:Y21) -> 8869.925 | ... AC22: =SUM(AC19:AC21) -> 8869.925 | AD22: =SUM(R22:AC22) -> 107473.1 | AE22: =SUM(AE19:AE21) -> 112216 | AF22: =AD22-AE22 -> -4742.9 | AG22: Subtotal | AH22: =SUM(AH19:AH21) -> 9009.1606 | AI22: =SUM(AI19:AI21) -> 9009.1606 | AJ22: =SUM(AJ19:AJ21) -> 11059.161 | AK22: =SUM(AK19:AK21) -> 9009.1606 | AL22: =SUM(AL19:AL21) -> 9009.1606 | AM22: =SUM(AM19:AM21) -> 9009.1606 | AN22: =SUM(AN19:AN21) -> 9009.1606 | AO22: =SUM(AO19:AO21) -> 9009.1606 | ... AS22: =SUM(AS19:AS21) -> 9009.1606 | AT22: =SUM(AH22:AS22) -> 110159.93 | AU22: Subtotal | AV22: =SUM(AV19:AV21) -> 9234.3896 | AW22: =SUM(AW19:AW21) -> 9234.3896 | AX22: =SUM(AX19:AX21) -> 11335.64 | AY22: =SUM(AY19:AY21) -> 9234.3896 | AZ22: =SUM(AZ19:AZ21) -> 9234.3896 | BA22: =SUM(BA19:BA21) -> 9234.3896 | BB22: =SUM(BB19:BB21) -> 9234.3896 | BC22: =SUM(BC19:BC21) -> 9234.3896 | ... BG22: =SUM(BG19:BG21) -> 9234.3896 | BH22: =SUM(AV22:BG22) -> 112913.93 | BI22: Subtotal | BJ22: =SUM(BJ19:BJ21) -> 9465.2494 | BK22: =SUM(BK19:BK21) -> 9465.2494 | BL22: =SUM(BL19:BL21) -> 11619.031 | BM22: =SUM(BM19:BM21) -> 9465.2494 | BN22: =SUM(BN19:BN21) -> 9465.2494 | BO22: =SUM(BO19:BO21) -> 9465.2494 | BP22: =SUM(BP19:BP21) -> 9465.2494 | BQ22: =SUM(BQ19:BQ21) -> 9465.2494 | ... BU22: =SUM(BU19:BU21) -> 9465.2494 | BV22: =SUM(BJ22:BU22) -> 115736.77 | BW22: Subtotal | BX22: =SUM(BX19:BX21) -> 118630.19 | BY22: =SUM(BY19:BY21) -> 121595.95 | BZ22: =SUM(BZ19:BZ21) -> 124635.85 | CA22: =SUM(CA19:CA21) -> 127751.74 | CB22: =SUM(CB19:CB21) -> 130945.54 | CC22: =SUM(CC19:CC21) -> 134219.17 | CD22: =SUM(CD19:CD21) -> 137574.65 | CE22: =SUM(CE19:CE21) -> 141014.02 | ... CX22: =SUM(CX19:CX21) -> 225432.09
A23: Maintenance and Repairs | Q23: Maintenance and Repairs | AG23: Maintenance and Repairs | AU23: Maintenance and Repairs | BI23: Maintenance and Repairs | BW23: Maintenance and Repairs | BX23: =BV23
A24: Equipment Repairs (and purchases) | B24: 0 | C24: 0 | D24: 0 | E24: 636 | F24: 0 | G24: 32 | H24: 190 | I24: 528 | J24: 105 | K24: 863 | L24: 105 | M24: 110 | N24: =SUM(B24:M24) -> 2569 | O24: 1265 | P24: =N24-O24 -> 1304 | Q24: Equipment Repairs (and purchases) | R24: =(AE24/12) -> 164.08333 | S24: =R24 -> 164.08333 | T24: =S24 -> 164.08333 | U24: =T24 -> 164.08333 | V24: =U24 -> 164.08333 | W24: =V24 -> 164.08333 | X24: =W24 -> 164.08333 | Y24: =X24 -> 164.08333 | Z24: =Y24 -> 164.08333 | ... AC24: =AB24 -> 164.08333 | AD24: =SUM(R24:AC24) -> 1969 | AE24: 1969 | AF24: =AD24-AE24 -> 0 | AG24: Equipment Repairs | AH24: =R24*(1+(Inflation!$G$6)) -> 168.18542 | AI24: =S24*(1+(Inflation!$G$6)) -> 168.18542 | AJ24: =T24*(1+(Inflation!$G$6)) -> 168.18542 | AK24: =U24*(1+(Inflation!$G$6)) -> 168.18542 | AL24: =V24*(1+(Inflation!$G$6)) -> 168.18542 | AM24: =W24*(1+(Inflation!$G$6)) -> 168.18542 | AN24: =X24*(1+(Inflation!$G$6)) -> 168.18542 | AO24: =Y24*(1+(Inflation!$G$6)) -> 168.18542 | ... AS24: =AC24*(1+(Inflation!$G$6)) -> 168.18542 | AT24: =SUM(AH24:AS24) -> 2018.225 | AU24: Equipment Repairs | AV24: =AH24*(1+(Inflation!$H$6)) -> 172.39005 | AW24: =AI24*(1+(Inflation!$H$6)) -> 172.39005 | AX24: =AJ24*(1+(Inflation!$H$6)) -> 172.39005 | AY24: =AK24*(1+(Inflation!$H$6)) -> 172.39005 | AZ24: =AL24*(1+(Inflation!$H$6)) -> 172.39005 | BA24: =AM24*(1+(Inflation!$H$6)) -> 172.39005 | BB24: =AN24*(1+(Inflation!$H$6)) -> 172.39005 | BC24: =AO24*(1+(Inflation!$H$6)) -> 172.39005 | ... BG24: =AS24*(1+(Inflation!$H$6)) -> 172.39005 | BH24: =SUM(AV24:BG24) -> 2068.6806 | BI24: Equipment Repairs | BJ24: =AV24*(1+(Inflation!$I$6)) -> 176.6998 | BK24: =AW24*(1+(Inflation!$H$6)) -> 176.6998 | BL24: =AX24*(1+(Inflation!$H$6)) -> 176.6998 | BM24: =AY24*(1+(Inflation!$H$6)) -> 176.6998 | BN24: =AZ24*(1+(Inflation!$H$6)) -> 176.6998 | BO24: =BA24*(1+(Inflation!$H$6)) -> 176.6998 | BP24: =BB24*(1+(Inflation!$H$6)) -> 176.6998 | BQ24: =BC24*(1+(Inflation!$H$6)) -> 176.6998 | BR24: =BD24*(1+(Inflation!$H$6)) -> 176.6998 | ... BU24: =BG24*(1+(Inflation!$H$6)) -> 176.6998 | BV24: =SUM(BJ24:BU24) -> 2120.3976 | BW24: Equipment Repairs | BX24: =BV24*(1+Inflation!$J$4) -> 2188.2504 | BY24: =BX24*(1+Inflation!$J$4) -> 2258.2744 | BZ24: =BY24*(1+Inflation!$J$4) -> 2330.5392 | CA24: =BZ24*(1+Inflation!$J$4) -> 2405.1164 | CB24: =CA24*(1+Inflation!$J$4) -> 2482.0801 | CC24: =CB24*(1+Inflation!$J$4) -> 2561.5067 | CD24: =CC24*(1+Inflation!$J$4) -> 2643.4749 | CE24: =CD24*(1+Inflation!$J$4) -> 2728.0661 | CF24: =CE24*(1+Inflation!$J$4) -> 2815.3642 | ... CX24: =CW24*(1+Inflation!$J$4) -> 4963.2841
A25: Grounds Maintenance (Jaquez Contract) | B25: 0 | C25: 3756 | D25: 11268 | E25: 3756 | F25: 0 | G25: 7541 | H25: 12187 | I25: 5634 | J25: 1199 | K25: 19060 | L25: 3748 | M25: 3748 | N25: =SUM(B25:M25) -> 71897 | O25: 65000 | P25: =N25-O25 -> 6897 | Q25: Grounds Maintenance | R25: =(AE25/12) -> 5156.1667 | S25: =R25 -> 5156.1667 | T25: =S25 -> 5156.1667 | U25: =T25 -> 5156.1667 | V25: =U25 -> 5156.1667 | W25: =V25 -> 5156.1667 | X25: =W25 -> 5156.1667 | Y25: =X25 -> 5156.1667 | Z25: =Y25 -> 5156.1667 | ... AC25: =AB25 -> 5156.1667 | AD25: =SUM(R25:AC25) -> 61874 | AE25: 61874 | AF25: =AD25-AE25 -> 0 | AG25: Grounds Maintenance | AH25: =(AD25/12)*(1+(Inflation!$F$5)) -> 5285.0708 | AI25: =AH25 -> 5285.0708 | AJ25: =AI25 -> 5285.0708 | AK25: =AJ25 -> 5285.0708 | AL25: =AK25 -> 5285.0708 | AM25: =AL25 -> 5285.0708 | AN25: =AM25 -> 5285.0708 | AO25: =AN25 -> 5285.0708 | AP25: =AO25 -> 5285.0708 | ... AS25: =AR25 -> 5285.0708 | AT25: =SUM(AH25:AS25) -> 63420.85 | AU25: Grounds Maintenance | AV25: =(AT25/12)*(1+(Inflation!$F$5)) -> 5417.1976 | AW25: =AV25 -> 5417.1976 | AX25: =AW25 -> 5417.1976 | AY25: =AX25 -> 5417.1976 | AZ25: =AY25 -> 5417.1976 | BA25: =AZ25 -> 5417.1976 | BB25: =BA25 -> 5417.1976 | BC25: =BB25 -> 5417.1976 | BD25: =BC25 -> 5417.1976 | ... BG25: =BF25 -> 5417.1976 | BH25: =SUM(AV25:BG25) -> 65006.371 | BI25: Grounds Maintenance | BJ25: =(BH25/12)*(1+(Inflation!$F$5)) -> 5552.6275 | BK25: =BJ25 -> 5552.6275 | BL25: =BK25 -> 5552.6275 | BM25: =BL25 -> 5552.6275 | BN25: =BM25 -> 5552.6275 | BO25: =BN25 -> 5552.6275 | BP25: =BO25 -> 5552.6275 | BQ25: =BP25 -> 5552.6275 | BR25: =BQ25 -> 5552.6275 | ... BU25: =BT25 -> 5552.6275 | BV25: =SUM(BJ25:BU25) -> 66631.531 | BW25: Grounds Maintenance | BX25: =BV25*(1+Inflation!$J$5) -> 68297.319 | BY25: =BX25*(1+Inflation!$J$5) -> 70004.752 | BZ25: =BY25*(1+Inflation!$J$5) -> 71754.871 | CA25: =BZ25*(1+Inflation!$J$5) -> 73548.742 | CB25: =CA25*(1+Inflation!$J$5) -> 75387.461 | CC25: =CB25*(1+Inflation!$J$5) -> 77272.147 | CD25: =CC25*(1+Inflation!$J$5) -> 79203.951 | CE25: =CD25*(1+Inflation!$J$5) -> 81184.05 | CF25: =CE25*(1+Inflation!$J$5) -> 83213.651 | ... CX25: =CW25*(1+Inflation!$J$5) -> 129784.9
A26: Facility Maintenance (Misc Repairs) | B26: 19878 | C26: 256 | D26: 7540 | E26: 366 | F26: 365 | G26: 139 | H26: 12669 | I26: 2939 | J26: 13845 | K26: 14929 | L26: 0 | M26: =(sum($C26:$H26)/6) -> 3555.8333 | N26: =SUM(B26:M26) -> 76481.833 | O26: 60820 | P26: =N26-O26 -> 15661.833 | Q26: Facility Maintenance (Misc Repairs) | R26: 5991 | S26: =R26 -> 5991 | T26: =S26 -> 5991 | U26: =T26 -> 5991 | V26: =U26 -> 5991 | W26: =V26 -> 5991 | X26: =W26 -> 5991 | Y26: =X26 -> 5991 | Z26: =Y26 -> 5991 | ... AC26: =AB26 -> 5991 | AD26: =SUM(R26:AC26) -> 71892 | AE26: 71892 | AF26: =AD26-AE26 -> 0 | AG26: Facility Maintenance (Misc Repairs) | AH26: =(AC26)*(1+(Inflation!$F$2)) -> 6212.667 | AI26: =AH26 -> 6212.667 | AJ26: =AI26 -> 6212.667 | AK26: =AJ26 -> 6212.667 | AL26: =AK26 -> 6212.667 | AM26: =AL26 -> 6212.667 | AN26: =AM26 -> 6212.667 | AO26: =AN26 -> 6212.667 | AP26: =AO26 -> 6212.667 | ... AS26: =AR26 -> 6212.667 | AT26: =SUM(AH26:AS26) -> 74552.004 | AU26: Facility Maintenance (Misc Repairs) | AV26: =(AS26)*(1+(Inflation!$F$2)) -> 6442.5357 | AW26: =AV26 -> 6442.5357 | AX26: =AW26 -> 6442.5357 | AY26: =AX26 -> 6442.5357 | AZ26: =AY26 -> 6442.5357 | BA26: =AZ26 -> 6442.5357 | BB26: =BA26 -> 6442.5357 | BC26: =BB26 -> 6442.5357 | BD26: =BC26 -> 6442.5357 | ... BG26: =BF26 -> 6442.5357 | BH26: =SUM(AV26:BG26) -> 77310.428 | BI26: Facility Maintenance (Misc Repairs) | BJ26: =(BG26)*(1+(Inflation!$F$2)) -> 6680.9095 | BK26: =BJ26 -> 6680.9095 | BL26: =BK26 -> 6680.9095 | BM26: =BL26 -> 6680.9095 | BN26: =BM26 -> 6680.9095 | BO26: =BN26 -> 6680.9095 | BP26: =BO26 -> 6680.9095 | BQ26: =BP26 -> 6680.9095 | BR26: =BQ26 -> 6680.9095 | ... BU26: =BT26 -> 6680.9095 | BV26: =SUM(BJ26:BU26) -> 80170.914 | BW26: Facility Maintenance (Misc Repairs) | BX26: =BV26*(1+(Inflation!$F$2)) -> 83137.238 | BY26: =BX26*(1+(Inflation!$F$2)) -> 86213.316 | BZ26: =BY26*(1+Inflation!$J$4) -> 88972.142 | CA26: =BZ26*(1+Inflation!$J$4) -> 91819.25 | CB26: =CA26*(1+Inflation!$J$4) -> 94757.466 | CC26: =CB26*(1+Inflation!$J$4) -> 97789.705 | CD26: =CC26*(1+Inflation!$J$4) -> 100918.98 | CE26: =CD26*(1+Inflation!$J$4) -> 104148.38 | CF26: =CE26*(1+Inflation!$J$4) -> 107481.13 | CG26: =CF26*(1+Inflation!$J$4) -> 110920.53 | ... CX26: =CW26*(1+Inflation!$J$4) -> 189481.49
A27: Facilities Maintenance (Detail in Line 51): | B27: =B82 -> 27685 | C27: =C82 -> 0 | D27: =D82 -> 25659.5 | E27: =E82 -> 0 | F27: =F82 -> 0 | G27: =G82 -> 10000 | H27: =H82 -> 170108 | I27: =I82 -> 90246 | ... M27: =M82 -> 134702.27 | N27: =SUM(B27:M27) -> 636583.77 | O27: 807000 | P27: =N27-O27 -> -170416.23 | Q27: Facilities Maintenance (Detail in Line 52): | R27: =R82 -> 0 | S27: =S82 -> 0 | T27: =T82 -> 0 | U27: =U82 -> 0 | V27: =V82 -> 10000 | W27: =W82 -> 191226 | X27: =X82 -> 114983.64 | Y27: =Y82 -> 72575.56 | ... AC27: =AC82 -> 0 | AD27: =SUM(R27:AC27) -> 648525 | AE27: 566158 | AF27: =AD27-AE27 -> 82367 | AG27: Facilities Maintenance (Detail in Line 52): | AH27: =AH82 -> 0 | AI27: =AI82 -> 0 | AJ27: =AJ82 -> 0 | AK27: =AK82 -> 27855.397 | AL27: =AL82 -> 32870.206 | AM27: =AM82 -> 156810.6 | AN27: =AN82 -> 48000 | AO27: =AO82 -> 6000 | ... AS27: =AS82 -> 0 | AT27: =SUM(AH27:AS27) -> 276536.2 | AU27: Facilities Maintenance (Detail in Line 52): | AV27: =AV82 -> 0 | AW27: =AW82 -> 0 | AX27: =AX82 -> 0 | AY27: =AY82 -> 16019.026 | AZ27: =AZ82 -> 152076.66 | BA27: =BA82 -> 0 | BB27: =BB82 -> 0 | BC27: =BC82 -> 628.09583 | ... BG27: =BG82 -> 0 | BH27: =SUM(AV27:BG27) -> 179370.75 | BI27: Facilities Maintenance (Detail in Line 52): | BJ27: =BJ82 -> 0 | BK27: =BK82 -> 0 | BL27: =BL82 -> 0 | BM27: =BM82 -> 16531.635 | BN27: =BN82 -> 0 | BO27: =BO82 -> 0 | BP27: =BP82 -> 0 | BQ27: =BQ82 -> 650.62547 | ... BU27: =BU82 -> 0 | BV27: =SUM(BJ27:BU27) -> 22538.385 | BW27: Facilities Maintenance (Detail in Line 52): | BX27: =BX82 -> 23606.178 | BY27: =BY82 -> 24386.905 | BZ27: =BZ82 -> 147954.68 | CA27: =CA82 -> 26026.896 | CB27: =CB82 -> 26887.911 | CC27: =CC82 -> 581253.15 | CD27: =CD82 -> 565255.06 | CE27: =CE82 -> 474289.91 | ... CX27: =CX82 -> 55059.731
A28: Pool Maintenance | F28: 1900 | G28: 1581 | H28: 1746 | I28: 2500 | J28: 886 | L28: 711 | N28: =SUM(B28:M28) -> 9324 | O28: 10000 | P28: =N28-O28 -> -676 | Q28: Pool Maintenance | V28: =(AE28/4) -> 2212.5 | W28: =V28 -> 2212.5 | X28: =W28 -> 2212.5 | Y28: =X28 -> 2212.5 | AD28: =SUM(R28:AC28) -> 8850 | AE28: 8850 | AF28: =AD28-AE28 -> 0 | AG28: Pool Maintenance | AL28: =(AD28/4)*(1+Inflation!$D$4) -> 2273.3438 | AM28: =AL28 -> 2273.3438 | AN28: =AM28 -> 2273.3438 | AO28: =AN28 -> 2273.3438 | AT28: =SUM(AH28:AS28) -> 9093.375 | AU28: Pool Maintenance | AZ28: =(AT28/4)*(1+Inflation!$D$4) -> 2335.8607 | BA28: =AZ28 -> 2335.8607 | BB28: =BA28 -> 2335.8607 | BC28: =BB28 -> 2335.8607 | BH28: =SUM(AV28:BG28) -> 9343.4428 | BI28: Pool Maintenance | BN28: =(BH28/4)*(1+Inflation!$D$4) -> 2400.0969 | BO28: =BN28 -> 2400.0969 | BP28: =BO28 -> 2400.0969 | BQ28: =BP28 -> 2400.0969 | BV28: =SUM(BJ28:BU28) -> 9600.3875 | BW28: Pool Maintenance | BX28: =BV28*(1+Inflation!$J$4) -> 9907.5999 | BY28: =BX28*(1+Inflation!$J$4) -> 10224.643 | BZ28: =BY28*(1+Inflation!$J$4) -> 10551.832 | CA28: =BZ28*(1+Inflation!$J$4) -> 10889.49 | CB28: =CA28*(1+Inflation!$J$4) -> 11237.954 | CC28: =CB28*(1+Inflation!$J$4) -> 11597.568 | CD28: =CC28*(1+Inflation!$J$4) -> 11968.691 | CE28: =CD28*(1+Inflation!$J$4) -> 12351.689 | CF28: =CE28*(1+Inflation!$J$4) -> 12746.943 | ... CX28: =CW28*(1+Inflation!$J$4) -> 22471.941
A29: Rental Unit Maintenance | B29: 5798 | C29: 1438 | D29: 288 | E29: 0 | F29: 125 | G29: 0 | H29: 71 | I29: 125 | J29: 0 | K29: 125 | L29: 0 | M29: 125 | N29: =SUM(B29:M29) -> 8095 | O29: 1500 | P29: =N29-O29 -> 6595 | Q29: Rental Unit Maintenance | R29: =AE29/12 -> 128.16667 | S29: =R29 -> 128.16667 | T29: =S29 -> 128.16667 | U29: =T29 -> 128.16667 | V29: =U29 -> 128.16667 | W29: =V29 -> 128.16667 | X29: =W29 -> 128.16667 | Y29: =X29 -> 128.16667 | Z29: =Y29 -> 128.16667 | ... AC29: =AB29 -> 128.16667 | AD29: =SUM(R29:AC29) -> 1538 | AE29: 1538 | AF29: =AD29-AE29 -> 0 | AG29: Rental Unit Maintenance | AH29: =AC29*(1+(Inflation!$F$6)) -> 131.37083 | AI29: =AH29 -> 131.37083 | AJ29: =AI29 -> 131.37083 | AK29: =AJ29 -> 131.37083 | AL29: =AK29 -> 131.37083 | AM29: =AL29 -> 131.37083 | AN29: =AM29 -> 131.37083 | AO29: =AN29 -> 131.37083 | AP29: =AO29 -> 131.37083 | ... AS29: =AR29 -> 131.37083 | AT29: =SUM(AH29:AS29) -> 1576.45 | AU29: Rental Unit Maintenance | AV29: =AS29*(1+(Inflation!$F$6)) -> 134.6551 | AW29: =AV29 -> 134.6551 | AX29: =AW29 -> 134.6551 | AY29: =AX29 -> 134.6551 | AZ29: =AY29 -> 134.6551 | BA29: =AZ29 -> 134.6551 | BB29: =BA29 -> 134.6551 | BC29: =BB29 -> 134.6551 | BD29: =BC29 -> 134.6551 | ... BG29: =BF29 -> 134.6551 | BH29: =SUM(AV29:BG29) -> 1615.8612 | BI29: Rental Unit Maintenance | BJ29: =BG29*(1+(Inflation!$F$6)) -> 138.02148 | BK29: =BJ29 -> 138.02148 | BL29: =BK29 -> 138.02148 | BM29: =BL29 -> 138.02148 | BN29: =BM29 -> 138.02148 | BO29: =BN29 -> 138.02148 | BP29: =BO29 -> 138.02148 | BQ29: =BP29 -> 138.02148 | BR29: =BQ29 -> 138.02148 | ... BU29: =BT29 -> 138.02148 | BV29: =SUM(BJ29:BU29) -> 1656.2578 | BW29: Rental Unit Maintenance | BX29: =BV29*(1+Inflation!$J$4) -> 1709.258 | BY29: =BX29*(1+Inflation!$J$4) -> 1763.9543 | BZ29: =BY29*(1+Inflation!$J$4) -> 1820.4008 | CA29: =BZ29*(1+Inflation!$J$4) -> 1878.6537 | CB29: =CA29*(1+Inflation!$J$4) -> 1938.7706 | CC29: =CB29*(1+Inflation!$J$4) -> 2000.8112 | CD29: =CC29*(1+Inflation!$J$4) -> 2064.8372 | CE29: =CD29*(1+Inflation!$J$4) -> 2130.912 | CF29: =CE29*(1+Inflation!$J$4) -> 2199.1012 | ... CX29: =CW29*(1+Inflation!$J$4) -> 3876.8568
A30: Snow Removal & Purchase Snow-Melt | B30: 0 | C30: 0 | D30: 2802 | E30: 10276 | M30: 4595 | N30: =SUM(B30:M30) -> 17673 | O30: 18380 | P30: =N30-O30 -> -707 | Q30: Snow Removal & Purchase Snow-Melt | R30: =(AE30/4) -> 4809.75 | S30: =R30 -> 4809.75 | T30: =S30 -> 4809.75 | AC30: =T30 -> 4809.75 | AD30: =SUM(R30:AC30) -> 19239 | AE30: 19239 | AF30: =AD30-AE30 -> 0 | AG30: Snow Removal & Purchase Snow-Melt | AH30: =(AD30/4)*(1+Inflation!$G$4)+1000 -> 5963.662 | AI30: =(AD30/4)*(1+Inflation!$G$4) -> 4963.662 | AJ30: =AI30 -> 4963.662 | AS30: =AJ30 -> 4963.662 | AT30: =SUM(AH30:AS30) -> 20854.648 | AU30: Snow Removal & Purchase Snow-Melt | AV30: =(AT30/4)*(1+Inflation!$H$4)+1000 -> 6380.4992 | AW30: =(AT30/4)*(1+Inflation!$H$4) -> 5380.4992 | AX30: =AW30 -> 5380.4992 | BG30: =AX30 -> 5380.4992 | BH30: =SUM(AV30:BG30) -> 22521.997 | BI30: Snow Removal & Purchase Snow-Melt | BJ30: =(BH30/4)*(1+Inflation!$I$4)+1000 -> 6810.6752 | BK30: =(BH30/4)*(1+Inflation!$H$4) -> 5810.6752 | BL30: =BK30 -> 5810.6752 | BU30: =BL30 -> 5810.6752 | BV30: =SUM(BJ30:BU30) -> 24242.701 | BW30: Snow Removal & Purchase Snow-Melt | BX30: =BV30*(1+Inflation!$J$4) -> 25018.467 | BY30: =BX30*(1+Inflation!$J$4) -> 25819.058 | BZ30: =BY30*(1+Inflation!$J$4) -> 26645.268 | CA30: =BZ30*(1+Inflation!$J$4) -> 27497.916 | CB30: =CA30*(1+Inflation!$J$4) -> 28377.85 | CC30: =CB30*(1+Inflation!$J$4) -> 29285.941 | CD30: =CC30*(1+Inflation!$J$4) -> 30223.091 | CE30: =CD30*(1+Inflation!$J$4) -> 31190.23 | CF30: =CE30*(1+Inflation!$J$4) -> 32188.317 | ... CX30: =CW30*(1+Inflation!$J$4) -> 56745.683
A31: Subtotal | B31: =SUM(B24:B30) -> 53361 | C31: =SUM(C24:C30) -> 5450 | D31: =SUM(D24:D30) -> 47557.5 | E31: =SUM(E24:E30) -> 15034 | F31: =SUM(F24:F30) -> 2390 | G31: =SUM(G24:G30) -> 19293 | H31: =SUM(H24:H30) -> 196971 | I31: =SUM(I24:I30) -> 101972 | ... M31: =SUM(M24:M30) -> 146836.1 | N31: =SUM(B31:M31) -> 822623.6 | O31: =SUM(O24:O30) -> 963965 | P31: =N31-O31 -> -141341.4 | Q31: Subtotal | R31: =SUM(R24:R30) -> 16249.167 | S31: =SUM(S24:S30) -> 16249.167 | T31: =SUM(T24:T30) -> 16249.167 | U31: =SUM(U24:U30) -> 11439.417 | V31: =SUM(V24:V30) -> 23651.917 | W31: =SUM(W24:W30) -> 204877.92 | X31: =SUM(X24:X30) -> 128635.56 | Y31: =SUM(Y24:Y30) -> 86227.477 | ... AC31: =SUM(AC24:AC30) -> 16249.167 | AD31: =SUM(R31:AC31) -> 813887 | AE31: =SUM(AE24:AE30) -> 731520 | AF31: =AD31-AE31 -> 82367 | AG31: Subtotal | AH31: =SUM(AH24:AH30) -> 17760.956 | AI31: =SUM(AI24:AI30) -> 16760.956 | AJ31: =SUM(AJ24:AJ30) -> 16760.956 | AK31: =SUM(AK24:AK30) -> 39652.691 | AL31: =SUM(AL24:AL30) -> 46940.844 | AM31: =SUM(AM24:AM30) -> 170881.24 | AN31: =SUM(AN24:AN30) -> 62070.638 | AO31: =SUM(AO24:AO30) -> 20070.638 | ... AS31: =SUM(AS24:AS30) -> 16760.956 | AT31: =SUM(AH31:AS31) -> 448051.75 | AU31: Subtotal | AV31: =SUM(AV24:AV30) -> 18547.278 | AW31: =SUM(AW24:AW30) -> 17547.278 | AX31: =SUM(AX24:AX30) -> 17547.278 | AY31: =SUM(AY24:AY30) -> 28185.804 | AZ31: =SUM(AZ24:AZ30) -> 166579.3 | BA31: =SUM(BA24:BA30) -> 14502.639 | BB31: =SUM(BB24:BB30) -> 14502.639 | BC31: =SUM(BC24:BC30) -> 15130.735 | ... BG31: =SUM(BG24:BG30) -> 17547.278 | BH31: =SUM(AV31:BG31) -> 357237.53 | BI31: Subtotal | BJ31: =SUM(BJ24:BJ30) -> 19358.933 | BK31: =SUM(BK24:BK30) -> 18358.933 | BL31: =SUM(BL24:BL30) -> 18358.933 | BM31: =SUM(BM24:BM30) -> 29079.893 | BN31: =SUM(BN24:BN30) -> 14948.355 | BO31: =SUM(BO24:BO30) -> 14948.355 | BP31: =SUM(BP24:BP30) -> 14948.355 | BQ31: =SUM(BQ24:BQ30) -> 15598.981 | ... BU31: =SUM(BU24:BU30) -> 18358.933 | BV31: =SUM(BJ31:BU31) -> 206960.57 | BW31: Subtotal | BX31: =SUM(BX24:BX30) -> 213864.31 | BY31: =SUM(BY24:BY30) -> 220670.9 | BZ31: =SUM(BZ24:BZ30) -> 350029.74 | CA31: =SUM(CA24:CA30) -> 234066.07 | CB31: =SUM(CB24:CB30) -> 241069.49 | CC31: =SUM(CC24:CC30) -> 801760.83 | CD31: =SUM(CD24:CD30) -> 792278.08 | CE31: =SUM(CE24:CE30) -> 708023.24 | ... CX31: =SUM(CX24:CX30) -> 462383.88
A32: Office Salary Expenses | Q32: Office Salary Expenses | AG32: Office Salary Expenses | AU32: Office Salary Expenses | BI32: Office Salary Expenses | BW32: Office Salary Expenses
A33: Business Office Salary | B33: 2131 | C33: 1227 | D33: 4727 | E33: 996 | F33: 1942 | G33: 2508 | H33: 8824 | I33: 3121 | J33: 3121 | K33: 3121 | L33: 3193 | M33: 3193 | N33: =SUM(B33:M33) -> 38104 | O33: 37447 | P33: =N33-O33 -> 657 | Q33: Business Office Salary | R33: =AE33/12 -> 4116.6667 | S33: =R33 -> 4116.6667 | T33: =S33 -> 4116.6667 | U33: =T33 -> 4116.6667 | V33: =U33 -> 4116.6667 | W33: =V33 -> 4116.6667 | X33: =W33 -> 4116.6667 | Y33: =X33 -> 4116.6667 | Z33: =Y33 -> 4116.6667 | ... AC33: =AB33 -> 4116.6667 | AD33: =SUM(R33:AC33) -> 49400 | AE33: 49400 | AF33: =AD33-AE33 -> 0 | AG33: Business Office Salary | AH33: =AC33*(1+(Inflation!$G$6)) -> 4219.5833 | AI33: =AH33 -> 4219.5833 | AJ33: =AI33 -> 4219.5833 | AK33: =AJ33 -> 4219.5833 | AL33: =AK33 -> 4219.5833 | AM33: =AL33 -> 4219.5833 | AN33: =AM33 -> 4219.5833 | AO33: =AN33 -> 4219.5833 | AP33: =AO33 -> 4219.5833 | ... AS33: =AR33 -> 4219.5833 | AT33: =SUM(AH33:AS33) -> 50635 | AU33: Business Office Salary | AV33: =AS33*(1+(Inflation!$H$6)) -> 4325.0729 | AW33: =AV33 -> 4325.0729 | AX33: =AW33 -> 4325.0729 | AY33: =AX33 -> 4325.0729 | AZ33: =AY33 -> 4325.0729 | BA33: =AZ33 -> 4325.0729 | BB33: =BA33 -> 4325.0729 | BC33: =BB33 -> 4325.0729 | BD33: =BC33 -> 4325.0729 | ... BG33: =BF33 -> 4325.0729 | BH33: =SUM(AV33:BG33) -> 51900.875 | BI33: Business Office Salary | BJ33: =BG33*(1+(Inflation!$I$6)) -> 4433.1997 | BK33: =BJ33 -> 4433.1997 | BL33: =BK33 -> 4433.1997 | BM33: =BL33 -> 4433.1997 | BN33: =BM33 -> 4433.1997 | BO33: =BN33 -> 4433.1997 | BP33: =BO33 -> 4433.1997 | BQ33: =BP33 -> 4433.1997 | BR33: =BQ33 -> 4433.1997 | ... BU33: =BT33 -> 4433.1997 | BV33: =SUM(BJ33:BU33) -> 53198.397 | BW33: Business Office Salary | BX33: =BV33*(1+Inflation!$J$5) -> 54528.357 | BY33: =BX33*(1+Inflation!$J$4) -> 56273.264 | BZ33: =BY33*(1+Inflation!$J$4) -> 58074.009 | CA33: =BZ33*(1+Inflation!$J$4) -> 59932.377 | CB33: =CA33*(1+Inflation!$J$4) -> 61850.213 | CC33: =CB33*(1+Inflation!$J$4) -> 63829.42 | CD33: =CC33*(1+Inflation!$J$4) -> 65871.961 | CE33: =CD33*(1+Inflation!$J$4) -> 67979.864 | CF33: =CE33*(1+Inflation!$J$4) -> 70155.22 | ... CX33: =CW33*(1+Inflation!$J$4) -> 123678.59
